<?xml version="1.0"?>
<robot name="selqie" xmlns:xacro="http://ros.org/wiki/xacro">

<!-- Material Macros -->
<xacro:macro name="aluminum">
    <material name="aluminum">
        <color rgba="0.5 0.5 0.5 1.0"/>
    </material>
</xacro:macro>

<xacro:macro name="pla">
    <material name="pla">
        <color rgba="0.1 0.1 0.1 1.0"/>
    </material>
</xacro:macro>

<xacro:property name="base_length" value="0.33"/>
<xacro:property name="base_width" value="0.15"/>
<xacro:property name="base_height" value="0.1"/>

<!-- Robot Base -->
<link name="base_link">
    <visual>
        <geometry>
            <box size="${base_length} ${base_width} ${base_height}"/>   
        </geometry>
        <xacro:aluminum/>
    </visual>
    <visual>
        <origin xyz="0 ${base_width/2} 0" rpy="0 1.5708 0"/>
        <geometry>
            <cylinder radius="${base_height/2}" length="${base_length}"/>   
        </geometry>
        <xacro:aluminum/> 
    </visual>
    <visual>
        <origin xyz="0 ${-base_width/2} 0" rpy="0 1.5708 0"/>
        <geometry>
            <cylinder radius="${base_height/2}" length="${base_length}"/>    
        </geometry>
        <xacro:aluminum/> 
    </visual>
</link>

<!-- Leg Properties -->
<xacro:property name="motor_box_length" value="0.15"/>
<xacro:property name="motor_box_width" value="0.1"/>
<xacro:property name="motor_box_height" value="0.1"/>
<xacro:property name="motor_box_xoff" value="0.27"/>
<xacro:property name="motor_box_yoff" value="0.075"/>

<xacro:property name="leg_link_margin" value="0.0005"/>

<xacro:property name="leg_thigh_length" value="0.066"/>
<xacro:property name="leg_thigh_width" value="0.01"/>
<xacro:property name="leg_thigh_height" value="0.015"/>
<xacro:property name="leg_thigh_joint_radius" value="0.0075"/>
<xacro:property name="leg_thigh_joint_length" value="0.01"/>
<xacro:property name="leg_thigh_xoff" value="0.03"/>
<xacro:property name="leg_thighA_yoff" value="${motor_box_width/2 + leg_link_margin}"/>
<xacro:property name="leg_thighB_yoff" value="${leg_thighA_yoff + leg_thigh_width + leg_link_margin}"/>

<xacro:property name="leg_calf_length" value="0.15"/>
<xacro:property name="leg_calf_width" value="0.005"/>
<xacro:property name="leg_calf_height" value="0.015"/>
<xacro:property name="leg_calf_joint_radius" value="0.0075"/>
<xacro:property name="leg_calf_joint_length" value="0.005"/>
<xacro:property name="leg_calf_xoff" value="${leg_thigh_length}"/>
<xacro:property name="leg_calfA_yoff" value="${leg_thigh_width + leg_link_margin}"/>
<xacro:property name="leg_calfB_yoff" value="${-leg_link_margin}"/>

<xacro:property name="toe_radius" value="0.015"/>
<xacro:property name="toe_length" value="0.01"/>
<xacro:property name="toe_xoff" value="${leg_calf_length}"/>
<xacro:property name="toe_yoff" value="${leg_link_margin}"/>

<!-- Legs -->
<xacro:macro name="leg" params="prefix x_reflect y_reflect motorA motorB">
    <!-- Motor Box -->
    <link name="${prefix}_motor_box">
        <visual>
            <geometry>
                <box size="${motor_box_length} ${motor_box_width} ${motor_box_height}"/>  
            </geometry>
            <xacro:aluminum/> 
        </visual>
    </link>

    <!-- Thigh A -->
    <link name="${prefix}_thighA">
        <visual>
            <origin xyz="${leg_thigh_length/2} ${y_reflect*leg_thigh_width/2} 0"/>
            <geometry>
                <box size="${leg_thigh_length} ${leg_thigh_width} ${leg_thigh_height}"/>   
            </geometry>
            <xacro:pla/> 
        </visual>
        <visual>
            <origin xyz="0 ${y_reflect*leg_thigh_width/2} 0" rpy="1.5708 0 0"/>
            <geometry>
                <cylinder radius="${leg_thigh_joint_radius}" length="${leg_thigh_joint_length}"/>  
            </geometry>
            <xacro:pla/> 
        </visual>
        <visual>
            <origin xyz="${leg_thigh_length} ${y_reflect*leg_thigh_width/2} 0" rpy="1.5708 0 0"/>
            <geometry>
                <cylinder radius="${leg_thigh_joint_radius}" length="${leg_thigh_joint_length}"/>     
            </geometry>
            <xacro:pla/> 
        </visual>
    </link>

    <!-- Calf A -->
    <link name="${prefix}_calfA">
        <visual>
            <origin xyz="${leg_calf_length/2} ${y_reflect*leg_calf_width/2} 0"/>
            <geometry>
                <box size="${leg_calf_length} ${leg_calf_width} ${leg_calf_height}"/>   
            </geometry>
            <xacro:pla/> 
        </visual>
        <visual>
            <origin xyz="0 ${y_reflect*leg_calf_width/2} 0" rpy="1.5708 0 0"/>
            <geometry>
                <cylinder radius="${leg_calf_joint_radius}" length="${leg_calf_joint_length}"/>  
            </geometry>
            <xacro:pla/> 
        </visual>

        <!-- Toe A -->
        <visual>
            <origin xyz="${leg_calf_length} ${y_reflect*leg_calf_width/2} 0" rpy="1.5708 0 0"/>
            <geometry>
                <cylinder radius="${toe_radius}" length="${toe_length}"/>  
            </geometry>
            <xacro:pla/> 
        </visual>
    </link>

    <!-- Thigh B -->
    <link name="${prefix}_thighB">
        <visual>
            <origin xyz="${leg_thigh_length/2} ${y_reflect*leg_thigh_width/2} 0"/>
            <geometry>
                <box size="${leg_thigh_length} ${leg_thigh_width} ${leg_thigh_height}"/>   
            </geometry>
            <xacro:pla/> 
        </visual>
        <visual>
            <origin xyz="0 ${y_reflect*leg_thigh_width/2} 0" rpy="1.5708 0 0"/>
            <geometry>
                <cylinder radius="${leg_thigh_joint_radius}" length="${leg_thigh_joint_length}"/>  
            </geometry>
            <xacro:pla/> 
        </visual>
        <visual>
            <origin xyz="${leg_thigh_length} ${y_reflect*leg_thigh_width/2} 0" rpy="1.5708 0 0"/>
            <geometry>
                <cylinder radius="${leg_thigh_joint_radius}" length="${leg_thigh_joint_length}"/>     
            </geometry>
            <xacro:pla/> 
        </visual>
    </link>

    <!-- Calf B -->
    <link name="${prefix}_calfB">
        <visual>
            <origin xyz="${leg_calf_length/2} ${y_reflect*leg_calf_width/2} 0"/>
            <geometry>
                <box size="${leg_calf_length} ${leg_calf_width} ${leg_calf_height}"/>   
            </geometry>
            <xacro:pla/> 
        </visual>
        <visual>
            <origin xyz="0 ${y_reflect*leg_calf_width/2} 0" rpy="1.5708 0 0"/>
            <geometry>
                <cylinder radius="${leg_calf_joint_radius}" length="${leg_calf_joint_length}"/>  
            </geometry>
            <xacro:pla/> 
        </visual>

        <!-- Toe B -->
        <visual>
            <origin xyz="${leg_calf_length} ${y_reflect*leg_calf_width/2} 0" rpy="1.5708 0 0"/>
            <geometry>
                <cylinder radius="${toe_radius}" length="${toe_length}"/>  
            </geometry>
            <xacro:pla/> 
        </visual>
    </link>

    <!-- Joints -->
    <joint name="${prefix}_motor_box_joint" type="fixed">
        <parent link="base_link"/>
        <child link="${prefix}_motor_box"/>
        <origin xyz="${x_reflect*motor_box_xoff} ${y_reflect*motor_box_yoff} 0"/>
    </joint>

    <joint name="motor${motorA}_link" type="continuous">
        <parent link="${prefix}_motor_box"/>
        <child link="${prefix}_thighA"/>
        <origin xyz="${x_reflect*leg_thigh_xoff} ${y_reflect*leg_thighA_yoff} 0"/>
        <axis xyz="0 ${-y_reflect} 0"/>
    </joint>

    <joint name="motor${motorB}_link" type="continuous">
        <parent link="${prefix}_motor_box"/>
        <child link="${prefix}_thighB"/>
        <origin xyz="${x_reflect*leg_thigh_xoff} ${y_reflect*leg_thighB_yoff} 0" rpy="0 3.1415926 0"/>
        <axis xyz="0 ${y_reflect} 0"/>
    </joint>

    <joint name="knee${motorA}_link" type="continuous">
        <parent link="${prefix}_thighA"/>
        <child link="${prefix}_calfA"/>
        <origin xyz="${leg_calf_xoff} ${y_reflect*leg_calfA_yoff} 0"/>
        <axis xyz="0 1 0"/>
    </joint>

    <joint name="knee${motorB}_link" type="continuous">
        <parent link="${prefix}_thighB"/>
        <child link="${prefix}_calfB"/>
        <origin xyz="${leg_calf_xoff} ${y_reflect*leg_calfA_yoff} 0"/>
        <axis xyz="0 -1 0"/>
    </joint>

</xacro:macro>

<xacro:leg prefix="legFL" x_reflect="+1" y_reflect="+1" motorA="0" motorB="1"/>
<xacro:leg prefix="legRL" x_reflect="-1" y_reflect="+1" motorA="2" motorB="3"/>
<xacro:leg prefix="legRR" x_reflect="-1" y_reflect="-1" motorA="4" motorB="5"/>
<xacro:leg prefix="legFR" x_reflect="+1" y_reflect="-1" motorA="6" motorB="7"/>

</robot>