<!-- SELQIE MuJoCo Model -->
<!-- Made by Jonathan Boylan -->
<!-- XML Docs: https://mujoco.readthedocs.io/en/stable/XMLreference.html -->
<mujoco model="selqie">
    <compiler angle="radian" autolimits="true"/>

    <!-- Parameters (in SI Units) -->
    <option timestep="0.001"/>
    <option integrator="implicit"/> <!-- Euler, RK4, implicit, implicitfast -->
    <option solver="Newton"/> <!-- PGS, CG, Newton -->
    <option gravity="0 0 -1.15"/>
    <option density="1000" viscosity="0.0009"/>

    <!-- Assets -->
    <asset>
        <material name="aluminum" shininess="0.25" rgba="0.5 0.5 0.5 1.0"/>
        <material name="pla" shininess="0" rgba="0.1 0.1 0.1 1.0"/>
    </asset>

    <!-- Model -->
    <worldbody>
        <light name="spotlight" mode="targetbodycom" target="base_link" pos="0 -1 2"/>

        <!-- Base Link Frame -->
        <body name="base_link" pos="0 0 0.5" euler="0 0 0">
            <freejoint/>

            <!-- Body -->
            <inertial pos="0 0 0" mass="10.0" diaginertia="0.0604 0.0310 0.0748"/>
            <geom type="box" size="0.165 0.075 0.05" material="aluminum"/>
            <geom type="cylinder" size="0.05 0.165" pos="0 0.075 0" euler="0 1.5708 0" material="aluminum"/>
            <geom type="cylinder" size="0.05 0.165" pos="0 -0.075 0" euler="0 1.5708 0" material="aluminum"/>

            <!-- Front Left Motor Box -->
            <body pos="0.27 0.075 0" euler="0 0 0">
                <inertial pos="0 0 0" mass="2.2" diaginertia="0.0037 0.0060 0.0060"/>
                <geom type="box" size="0.075 0.05 0.05" material="aluminum"/>

                <!-- Front Left Thigh A Frame -->
                <body pos="0.03 0.0505 0" euler="0 0 0">
                    <joint name="motor0" axis="0 -1 0"/>
                    <inertial pos="0.033 0.005 0" mass="0.01" diaginertia="0.0000003 0.000004 0.000004"/>
                    <geom type="cylinder" size="0.0075 0.005" pos="0 0.005 0" euler="1.5708 0 0" material="pla"/>
                    <geom type="box" size="0.033 0.005 0.0075" pos="0.033 0.005 0" material="pla"/>
                    <geom type="cylinder" size="0.0075 0.005" pos="0.066 0.005 0" euler="1.5708 0 0" material="pla"/>

                    <!-- Front Left Calf A Frame-->
                    <body pos="0.066 0.0105 0" euler="0 2.026395 0">
                        <joint axis="0 1 0"/>
                        <inertial pos="0.075 0.0025 0" mass="0.01" diaginertia="0.0000003 0.000002 0.000002"/>
                        <geom type="cylinder" size="0.0075 0.0025" pos="0 0.0025 0" euler="1.5708 0 0" material="pla"/>
                        <geom type="box" size="0.075 0.0025 0.0075" pos="0.075 0.0025 0" material="pla"/>

                        <!-- Front Left Toe A Frame -->
                        <body name="toeFLA" pos="0.15 -0.0005 0" euler="0 0 0">
                            <inertial pos="0 0.0055 0" mass="0.05" diaginertia="0.00005 0.00005 0.00005"/>
                            <geom type="cylinder" size="0.015 0.005" pos="0 0.0055 0" euler="1.5708 0 0" material="pla"/>
                        </body>
                    </body>
                </body>

                <!-- Front Left Thigh B Frame -->
                <body pos="0.03 0.061 0" euler="0 3.1415926 0">
                    <joint name="motor1" axis="0 1 0"/>
                    <inertial pos="0.033 0.005 0" mass="0.01" diaginertia="0.0000003 0.000004 0.000004"/>
                    <geom type="cylinder" size="0.0075 0.005" pos="0 0.005 0" euler="1.5708 0 0" material="pla"/>
                    <geom type="box" size="0.033 0.005 0.0075" pos="0.033 0.005 0" material="pla"/>
                    <geom type="cylinder" size="0.0075 0.005" pos="0.066 0.005 0" euler="1.5708 0 0" material="pla"/>

                    <!-- Front Left Calf B Frame-->
                    <body pos="0.066 -0.0005 0" euler="0 -2.026395 0">
                        <joint axis="0 1 0"/>
                        <inertial pos="0.075 -0.0025 0" mass="0.01" diaginertia="0.0000003 0.000002 0.000002"/>
                        <geom type="cylinder" size="0.0075 0.0025" pos="0 -0.0025 0" euler="1.5708 0 0" material="pla"/>
                        <geom type="box" size="0.075 0.0025 0.0075" pos="0.075 -0.0025 0" material="pla"/>

                        <!-- Front Left Toe B Frame -->
                        <body name="toeFLB" pos="0.15 0.0005 0" euler="0 0 0">
                            <inertial pos="0 -0.0055 0" mass="0.05" diaginertia="0.00005 0.00005 0.00005"/>
                            <geom type="cylinder" size="0.015 0.005" pos="0 -0.0055 0" euler="1.5708 0 0" material="pla"/>
                        </body>
                    </body>
                </body>
            </body>

            <!-- Rear Left Motor Box -->
            <body pos="-0.27 0.075 0" euler="0 0 0">
                <inertial pos="0 0 0" mass="2.2" diaginertia="0.0037 0.0060 0.0060"/>
                <geom type="box" size="0.075 0.05 0.05" material="aluminum"/>
                <!-- Rear Left Thigh A Frame -->
                <body pos="-0.03 0.0505 0" euler="0 0 0">
                    <joint name="motor2" axis="0 -1 0"/>
                    <inertial pos="0.033 0.005 0" mass="0.01" diaginertia="0.0000003 0.000004 0.000004"/>
                    <geom type="cylinder" size="0.0075 0.005" pos="0 0.005 0" euler="1.5708 0 0" material="pla"/>
                    <geom type="box" size="0.033 0.005 0.0075" pos="0.033 0.005 0" material="pla"/>
                    <geom type="cylinder" size="0.0075 0.005" pos="0.066 0.005 0" euler="1.5708 0 0" material="pla"/>

                    <!-- Rear Left Calf A Frame-->
                    <body pos="0.066 0.0105 0" euler="0 2.026395 0">
                        <joint axis="0 1 0"/>
                        <inertial pos="0.075 0.0025 0" mass="0.01" diaginertia="0.0000003 0.000002 0.000002"/>
                        <geom type="cylinder" size="0.0075 0.0025" pos="0 0.0025 0" euler="1.5708 0 0" material="pla"/>
                        <geom type="box" size="0.075 0.0025 0.0075" pos="0.075 0.0025 0" material="pla"/>

                        <!-- Rear Left Toe A Frame -->
                        <body name="toeRLA" pos="0.15 -0.0005 0" euler="0 0 0">
                            <inertial pos="0 0.0055 0" mass="0.05" diaginertia="0.00005 0.00005 0.00005"/>
                            <geom type="cylinder" size="0.015 0.005" pos="0 0.0055 0" euler="1.5708 0 0" material="pla"/>
                        </body>
                    </body>
                </body>

                <!-- Rear Left Thigh B Frame -->
                <body pos="-0.03 0.061 0" euler="0 3.1415926 0">
                    <joint name="motor3" axis="0 1 0"/>
                    <inertial pos="0.033 0.005 0" mass="0.01" diaginertia="0.0000003 0.000004 0.000004"/>
                    <geom type="cylinder" size="0.0075 0.005" pos="0 0.005 0" euler="1.5708 0 0" material="pla"/>
                    <geom type="box" size="0.033 0.005 0.0075" pos="0.033 0.005 0" material="pla"/>
                    <geom type="cylinder" size="0.0075 0.005" pos="0.066 0.005 0" euler="1.5708 0 0" material="pla"/>

                    <!-- Rear Left Calf B Frame-->
                    <body pos="0.066 -0.0005 0" euler="0 -2.026395 0">
                        <joint axis="0 1 0"/>
                        <inertial pos="0.075 -0.0025 0" mass="0.01" diaginertia="0.0000003 0.000002 0.000002"/>
                        <geom type="cylinder" size="0.0075 0.0025" pos="0 -0.0025 0" euler="1.5708 0 0" material="pla"/>
                        <geom type="box" size="0.075 0.0025 0.0075" pos="0.075 -0.0025 0" material="pla"/>

                        <!-- Rear Left Toe B Frame -->
                        <body name="toeRLB" pos="0.15 0.0005 0" euler="0 0 0">
                            <inertial pos="0 -0.0055 0" mass="0.05" diaginertia="0.00005 0.00005 0.00005"/>
                            <geom type="cylinder" size="0.015 0.005" pos="0 -0.0055 0" euler="1.5708 0 0" material="pla"/>
                        </body>
                    </body>
                </body>
            </body>

            <!-- Rear Right Motor Box -->
            <body pos="-0.27 -0.075 0" euler="0 0 0">
                <inertial pos="0 0 0" mass="2.2" diaginertia="0.0037 0.0060 0.0060"/>
                <geom type="box" size="0.075 0.05 0.05" material="aluminum"/>
                <!-- Rear Right Thigh A Frame -->
                <body pos="-0.03 -0.0505 0" euler="0 0 0">
                    <joint name="motor4" axis="0 1 0"/>
                    <inertial pos="0.033 -0.005 0" mass="0.01" diaginertia="0.0000003 0.000004 0.000004"/>
                    <geom type="cylinder" size="0.0075 0.005" pos="0 -0.005 0" euler="1.5708 0 0" material="pla"/>
                    <geom type="box" size="0.033 0.005 0.0075" pos="0.033 -0.005 0" material="pla"/>
                    <geom type="cylinder" size="0.0075 0.005" pos="0.066 -0.005 0" euler="1.5708 0 0" material="pla"/>

                    <!-- Rear Right Calf A Frame-->
                    <body pos="0.066 -0.0105 0" euler="0 2.026395 0">
                        <joint axis="0 1 0"/>
                        <inertial pos="0.075 -0.0025 0" mass="0.01" diaginertia="0.0000003 0.000002 0.000002"/>
                        <geom type="cylinder" size="0.0075 0.0025" pos="0 -0.0025 0" euler="1.5708 0 0" material="pla"/>
                        <geom type="box" size="0.075 0.0025 0.0075" pos="0.075 -0.0025 0" material="pla"/>

                        <!-- Rear Right Toe A Frame -->
                        <body name="toeRRA" pos="0.15 0.0005 0" euler="0 0 0">
                            <inertial pos="0 -0.0055 0" mass="0.05" diaginertia="0.00005 0.00005 0.00005"/>
                            <geom type="cylinder" size="0.015 0.005" pos="0 -0.0055 0" euler="1.5708 0 0" material="pla"/>
                        </body>
                    </body>
                </body>

                <!-- Rear Right Thigh B Frame -->
                <body pos="-0.03 -0.061 0" euler="0 3.1415926 0">
                    <joint name="motor5" axis="0 -1 0"/>
                    <inertial pos="0.033 -0.005 0" mass="0.01" diaginertia="0.0000003 0.000004 0.000004"/>
                    <geom type="cylinder" size="0.0075 0.005" pos="0 -0.005 0" euler="1.5708 0 0" material="pla"/>
                    <geom type="box" size="0.033 0.005 0.0075" pos="0.033 -0.005 0" material="pla"/>
                    <geom type="cylinder" size="0.0075 0.005" pos="0.066 -0.005 0" euler="1.5708 0 0" material="pla"/>

                    <!-- Rear Right Calf B Frame-->
                    <body pos="0.066 0.0005 0" euler="0 -2.026395 0">
                        <joint axis="0 1 0"/>
                        <inertial pos="0.075 0.0025 0" mass="0.01" diaginertia="0.0000003 0.000002 0.000002"/>
                        <geom type="cylinder" size="0.0075 0.0025" pos="0 0.0025 0" euler="1.5708 0 0" material="pla"/>
                        <geom type="box" size="0.075 0.0025 0.0075" pos="0.075 0.0025 0" material="pla"/>

                        <!-- Rear Right Toe B Frame -->
                        <body name="toeRRB" pos="0.15 -0.0005 0" euler="0 0 0">
                            <inertial pos="0 0.0055 0" mass="0.05" diaginertia="0.00005 0.00005 0.00005"/>
                            <geom type="cylinder" size="0.015 0.005" pos="0 0.0055 0" euler="1.5708 0 0" material="pla"/>
                        </body>
                    </body>
                </body>
            </body>

            <!-- Front Right Motor Box -->
            <body pos="0.27 -0.075 0" euler="0 0 0">
                <inertial pos="0 0 0" mass="2.2" diaginertia="0.0037 0.0060 0.0060"/>
                <geom type="box" size="0.075 0.05 0.05" material="aluminum"/>
                <!-- Front Right Thigh A Frame -->
                <body pos="0.03 -0.0505 0" euler="0 0 0">
                    <joint name="motor6" axis="0 1 0"/>
                    <inertial pos="0.033 -0.005 0" mass="0.01" diaginertia="0.0000003 0.000004 0.000004"/>
                    <geom type="cylinder" size="0.0075 0.005" pos="0 -0.005 0" euler="1.5708 0 0" material="pla"/>
                    <geom type="box" size="0.033 0.005 0.0075" pos="0.033 -0.005 0" material="pla"/>
                    <geom type="cylinder" size="0.0075 0.005" pos="0.066 -0.005 0" euler="1.5708 0 0" material="pla"/>

                    <!-- Front Right Calf A Frame-->
                    <body pos="0.066 -0.0105 0" euler="0 2.026395 0">
                        <joint axis="0 1 0"/>
                        <inertial pos="0.075 -0.0025 0" mass="0.01" diaginertia="0.0000003 0.000002 0.000002"/>
                        <geom type="cylinder" size="0.0075 0.0025" pos="0 -0.0025 0" euler="1.5708 0 0" material="pla"/>
                        <geom type="box" size="0.075 0.0025 0.0075" pos="0.075 -0.0025 0" material="pla"/>

                        <!-- Front Right Toe A Frame -->
                        <body name="toeFRA" pos="0.15 0.0005 0" euler="0 0 0">
                            <inertial pos="0 -0.0055 0" mass="0.05" diaginertia="0.00005 0.00005 0.00005"/>
                            <geom type="cylinder" size="0.015 0.005" pos="0 -0.0055 0" euler="1.5708 0 0" material="pla"/>
                        </body>
                    </body>
                </body>

                <!-- Front Right Thigh B Frame -->
                <body pos="0.03 -0.061 0" euler="0 3.1415926 0">
                    <joint name="motor7" axis="0 -1 0"/>
                    <inertial pos="0.033 -0.005 0" mass="0.01" diaginertia="0.0000003 0.000004 0.000004"/>
                    <geom type="cylinder" size="0.0075 0.005" pos="0 -0.005 0" euler="1.5708 0 0" material="pla"/>
                    <geom type="box" size="0.033 0.005 0.0075" pos="0.033 -0.005 0" material="pla"/>
                    <geom type="cylinder" size="0.0075 0.005" pos="0.066 -0.005 0" euler="1.5708 0 0" material="pla"/>

                    <!-- Front Right Calf B Frame-->
                    <body pos="0.066 0.0005 0" euler="0 -2.026395 0">
                        <joint axis="0 1 0"/>
                        <inertial pos="0.075 0.0025 0" mass="0.01" diaginertia="0.0000003 0.000002 0.000002"/>
                        <geom type="cylinder" size="0.0075 0.0025" pos="0 0.0025 0" euler="1.5708 0 0" material="pla"/>
                        <geom type="box" size="0.075 0.0025 0.0075" pos="0.075 0.0025 0" material="pla"/>

                        <!-- Front Right Toe B Frame -->
                        <body name="toeFRB" pos="0.15 -0.0005 0" euler="0 0 0">
                            <inertial pos="0 0.0055 0" mass="0.05" diaginertia="0.00005 0.00005 0.00005"/>
                            <geom type="cylinder" size="0.015 0.005" pos="0 0.0055 0" euler="1.5708 0 0" material="pla"/>
                        </body>
                    </body>
                </body>
            </body>

        </body>
    </worldbody>

    <equality>
        <connect body1="toeFLA" body2="toeFLB" anchor="0 0 0" solref="0.005 1" solimp="1 1 1 0 1"/>
        <connect body1="toeRLA" body2="toeRLB" anchor="0 0 0" solref="0.005 1" solimp="1 1 1 0 1"/>
        <connect body1="toeRRA" body2="toeRRB" anchor="0 0 0" solref="0.005 1" solimp="1 1 1 0 1"/>
        <connect body1="toeFRA" body2="toeFRB" anchor="0 0 0" solref="0.005 1" solimp="1 1 1 0 1"/>
    </equality>

    <!-- Actuators -->
    <actuator>
        <motor joint="motor0" ctrlrange="-10 10"/>
        <motor joint="motor1" ctrlrange="-10 10"/>
        <motor joint="motor2" ctrlrange="-10 10"/>
        <motor joint="motor3" ctrlrange="-10 10"/>
        <motor joint="motor4" ctrlrange="-10 10"/>
        <motor joint="motor5" ctrlrange="-10 10"/>
        <motor joint="motor6" ctrlrange="-10 10"/>
        <motor joint="motor7" ctrlrange="-10 10"/>
    </actuator>

</mujoco>